Workbook

Sheet 总览
A1: Agent / 具身智能 38 周学习计划 · 进度追踪
A2: 测试开发转型 ｜ 每周 10 小时 ｜ 2026-10-19 起 ｜ 预期 2027-07-11 完成
A3: 用法：每周日填写「周计划」里的实际工时、状态、自评；本页自动汇总。状态只有 4 个值，别自创。
A5: 计划总周数 | B5: =COUNTA(周计划!A2:A39)
A6: 计划总工时 | B6: =SUM(周计划!G2:G39)
A7: 已完成周数 | B7: =COUNTIF(周计划!I2:I39,"已完成")
A8: 进行中周数 | B8: =COUNTIF(周计划!I2:I39,"进行中")
A9: 延期周数 | B9: =COUNTIF(周计划!I2:I39,"延期")
A10: 完成率 | B10: =IFERROR(B7/B5,0)
A11: 累计实际工时 | B11: =SUM(周计划!H2:H39)
A12: 剩余工时（计划-实际） | B12: =B6-B11
A13: 平均自评（1-5） | B13: =IFERROR(AVERAGE(周计划!J2:J39),0)
A16: 阶段汇总
A17: 阶段 | C17: 周数 | D17: 计划工时 | E17: 已完成周 | F17: 完成率
A18: 阶段 0 地基 · 工程化与可测试服务 | C18: =COUNTIF(周计划!$D$2:$D$39,"阶段 0") | D18: =SUMIF(周计划!$D$2:$D$39,"阶段 0",周计划!$G$2:$G$39) | E18: =COUNTIFS(周计划!$D$2:$D$39,"阶段 0",周计划!$I$2:$I$39,"已完成") | F18: =IFERROR(E18/C18,0)
A19: 阶段 1 RAG · 检索增强与检索评估 | C19: =COUNTIF(周计划!$D$2:$D$39,"阶段 1") | D19: =SUMIF(周计划!$D$2:$D$39,"阶段 1",周计划!$G$2:$G$39) | E19: =COUNTIFS(周计划!$D$2:$D$39,"阶段 1",周计划!$I$2:$I$39,"已完成") | F19: =IFERROR(E19/C19,0)
A20: 阶段 2 Agent 核心 · Loop / Tool / Memory | C20: =COUNTIF(周计划!$D$2:$D$39,"阶段 2") | D20: =SUMIF(周计划!$D$2:$D$39,"阶段 2",周计划!$G$2:$G$39) | E20: =COUNTIFS(周计划!$D$2:$D$39,"阶段 2",周计划!$I$2:$I$39,"已完成") | F20: =IFERROR(E20/C20,0)
A21: 阶段 3 工程化 · 缓存 / 异步 / 观测 / 部署 | C21: =COUNTIF(周计划!$D$2:$D$39,"阶段 3") | D21: =SUMIF(周计划!$D$2:$D$39,"阶段 3",周计划!$G$2:$G$39) | E21: =COUNTIFS(周计划!$D$2:$D$39,"阶段 3",周计划!$I$2:$I$39,"已完成") | F21: =IFERROR(E21/C21,0)
A22: 弹性周 弹性周 · 春节缓冲 | C22: =COUNTIF(周计划!$D$2:$D$39,"弹性周") | D22: =SUMIF(周计划!$D$2:$D$39,"弹性周",周计划!$G$2:$G$39) | E22: =COUNTIFS(周计划!$D$2:$D$39,"弹性周",周计划!$I$2:$I$39,"已完成") | F22: =IFERROR(E22/C22,0)
A23: 阶段 4 评测 · 三层评测 + Eval Harness | C23: =COUNTIF(周计划!$D$2:$D$39,"阶段 4") | D23: =SUMIF(周计划!$D$2:$D$39,"阶段 4",周计划!$G$2:$G$39) | E23: =COUNTIFS(周计划!$D$2:$D$39,"阶段 4",周计划!$I$2:$I$39,"已完成") | F23: =IFERROR(E23/C23,0)
A24: 阶段 5 Multi-Agent 与两个项目 | C24: =COUNTIF(周计划!$D$2:$D$39,"阶段 5") | D24: =SUMIF(周计划!$D$2:$D$39,"阶段 5",周计划!$G$2:$G$39) | E24: =COUNTIFS(周计划!$D$2:$D$39,"阶段 5",周计划!$I$2:$I$39,"已完成") | F24: =IFERROR(E24/C24,0)
A25: 阶段 6 求职冲刺 · 简历与投递 | C25: =COUNTIF(周计划!$D$2:$D$39,"阶段 6") | D25: =SUMIF(周计划!$D$2:$D$39,"阶段 6",周计划!$G$2:$G$39) | E25: =COUNTIFS(周计划!$D$2:$D$39,"阶段 6",周计划!$I$2:$I$39,"已完成") | F25: =IFERROR(E25/C25,0)
A26: 阶段 B 具身 · 仿真 → 模仿学习 → VLA | C26: =COUNTIF(周计划!$D$2:$D$39,"阶段 B") | D26: =SUMIF(周计划!$D$2:$D$39,"阶段 B",周计划!$G$2:$G$39) | E26: =COUNTIFS(周计划!$D$2:$D$39,"阶段 B",周计划!$I$2:$I$39,"已完成") | F26: =IFERROR(E26/C26,0)

Sheet 周计划
A1: 周次 | B1: 开始日期 | C1: 结束日期 | D1: 阶段 | E1: 主线任务（工作日 5×1h 输入） | F1: 周末交付（可验收） | G1: 计划工时 | H1: 实际工时 | I1: 状态 | J1: 自评(1-5) | K1: 备注 / 卡点
A2: 1 | B2: 46314 | C2: 46320 | D2: 阶段 0 | E2: Python 工程化：uv/pyproject、类型注解 + Pydantic、async/httpx；调通一家 LLM API 并实现流式输出 | F2: CLI 流式问答：超时 / 重试 / --debug 打印 token 用量 | G2: 10 | I2: 未开始
A3: 2 | B3: 46321 | C3: 46327 | D3: 阶段 0 | E3: FastAPI 路由与依赖注入；pytest + fixture + mock LLM；Docker 基础 | F3: /chat 服务 + 8 条 pytest 全绿 + docker 一条命令起得来 | G3: 10 | I3: 未开始
A4: 3 | B4: 46328 | C4: 46334 | D4: 阶段 1 | E4: 文档加载与切分（PDF/MD，表格图片）、Embedding 原理、Chroma/FAISS 本地索引 | F4: 50 份 PDF 建索引，按引用回答问题 | G4: 10 | I4: 未开始
A5: 4 | B5: 46335 | C5: 46341 | D5: 阶段 1 | E5: 检索评估：先建 30 条评测集（问题 + 标准答案 + 应命中 chunk），再做 chunk 策略对比 | F5: 3 种 chunk 策略的 Recall@5 / MRR 对比表 | G5: 10 | I5: 未开始
A6: 5 | B6: 46342 | C6: 46348 | D6: 阶段 1 | E6: Advanced RAG：Query 改写（HyDE/Multi-Query）、BM25 + 向量混合检索、Reranker | F6: 混合检索 + rerank 后 Recall@5 相对基线提升 ≥10% | G6: 10 | I6: 未开始
A7: 6 | B7: 46349 | C7: 46355 | D7: 阶段 1 | E7: 生成侧评估（RAGAs：Faithfulness / Answer Relevancy）、Milvus 单机部署、Docker 打包 | F7: 端到端系统 + 评估报告（基线 vs 优化版四指标）【M1】 | G7: 10 | I7: 未开始
A8: 7 | B8: 46356 | C8: 46362 | D8: 阶段 2 | E8: 不用框架，手写 Agent Loop（150 行内）：dispatch 表注册工具、最大步数、超时、结构化输出解析 | F8: mini-agent：3 个工具 + 完整消息轨迹打印 | G8: 10 | I8: 未开始
A9: 8 | B9: 46363 | C9: 46369 | D9: 阶段 2 | E9: Function Calling 深入、工具 schema 与描述设计、错误重试与降级策略 | F9: 工具失败率对比实验：无重试 / 指数退避 / 降级兜底 | G9: 10 | I9: 未开始
A10: 9 | B10: 46370 | C10: 46376 | D10: 阶段 2 | E10: MCP：写一个自己的 MCP Server（本地文档检索），接入任意 MCP 客户端 | F10: 可被客户端调用的 Server + 契约测试 | G10: 10 | I10: 未开始
A11: 10 | B11: 46377 | C11: 46383 | D11: 阶段 2 | E11: Memory（短期 / 会话 / 长期）+ Context Engineering：分层上下文、压缩触发、检索注入 | F11: 跨会话记住用户偏好的助手 + 压缩前后 token 对比 | G11: 10 | I11: 未开始
A12: 11 | B12: 46384 | C12: 46390 | D12: 阶段 2 | E12: LangGraph 状态机：中断、人工确认、恢复；拆解一个真实 Harness 源码（Claude Code / OpenHands） | F12: research-agent（RAG + 搜索 + 引用）+ 一页 Harness 拆解笔记【M2】 | G12: 10 | I12: 未开始
A13: 12 | B13: 46391 | C13: 46397 | D13: 阶段 3 | E13: 性能剖析（py-spy / cProfile）、Redis 缓存（LLM 响应 + Embedding）、异步化改造 | F13: 优化前后 QPS / P99 对比表（目标 QPS ×3） | G13: 10 | I13: 未开始
... A39: 38 | B39: 46573 | C39: 46579 | D39: 阶段 B | E39: 收尾：技术报告、3 分钟演示视频、作品集整合、简历更新 | F39: demo 视频 + 技术报告 + 更新版简历【M6】 | G39: 10 | I39: 未开始

Sheet 周材料
A1: 逐周学习材料（点链接直接打开；材料名在 B 列，链接在 E 列）
A3: 周次 | B3: 日期 | C3: 日 | D3: 学什么 | E3: 材料 | F3: 备用材料 | G3: 1 行产出
A4: 1 | B4: 10/19–10/25 | C4: 周一 | D4: uv 与 pyproject：现代 Python 项目结构 | E4: uv 文档 | F4: — | G4: `uv run python -V` 能跑，依赖写进 pyproject
A5: 1 | B5: 10/19–10/25 | C5: 周二 | D5: 类型注解与 Pydantic v2 模型校验 | E5: Pydantic 文档 | F5: — | G5: 给 Message / Request 定义模型，非法输入能报错
A6: 1 | B6: 10/19–10/25 | C6: 周三 | D6: httpx 同步与异步请求、超时配置 | E6: httpx 文档 | F6: — | G6: 异步发一次请求并打印耗时
A7: 1 | B7: 10/19–10/25 | C7: 周四 | D7: 调通 LLM API，理解 messages 与计费 | E7: DeepSeek API 文档 | F7: — | G7: 拿到 key，跑通一次非流式调用并读到 usage
A8: 1 | B8: 10/19–10/25 | C8: 周五 | D8: 流式输出（SSE）与首 token 延迟 | E8: httpx 流式读取 | F8: — | G8: 逐块打印，记录 first-token 时间
A9: 1 | B9: 10/19–10/25 | C9: 周末 | D9: 实战：把 5 天碎片拼成一个 CLI：`ask "问题" --stream --d… | E9: 检索兜底：uv pyproject 入门；httpx 流式 SSE
A10: 2 | B10: 10/26–11/01 | C10: 周一 | D10: FastAPI 第一个接口、自动文档 | E10: FastAPI 教程 | F10: — | G10: `/health` 与 `/chat` 两个路由可用
A11: 2 | B11: 10/26–11/01 | C11: 周二 | D11: 请求体/响应模型与错误处理 | E11: FastAPI 请求体 | F11: — | G11: 参数校验失败返回 422 且信息可读
A12: 2 | B12: 10/26–11/01 | C12: 周三 | D12: 依赖注入：把 LLM 客户端做成可替换依赖 | E12: 依赖注入 | F12: — | G12: 测试时能注入假客户端
A13: 2 | B13: 10/26–11/01 | C13: 周四 | D13: pytest：fixture、参数化、monkeypatch 打桩 | E13: pytest 文档 | F13: monkeypatch | G13: 8 条用例，含 1 条超时与 1 条异常路径
A14: 2 | B14: 10/26–11/01 | C14: 周五 | D14: TestClient 写接口测试 | E14: FastAPI 测试 | F14: — | G14: 测试覆盖 200 / 422 / 500 三条路径
A15: 2 | B15: 10/26–11/01 | C15: 周末 | D15: 实战：写 Dockerfile，`docker build` + `docker … | E15: 检索兜底：fastapi pytest TestClient；docker python 镜像 slim
A16: 3 | B16: 11/02–11/08 | C16: 周一 | D16: 文档解析：PDF 表格、扫描件、Markdown | E16: Unstructured | F16: MinerU | G16: 50 份 PDF 能转成结构化文本，表格不塌
A17: 3 | B17: 11/02–11/08 | C17: 周二 | D17: 切分策略：固定窗口 / 递归 / 语义 / 父子块 | E17: Chunking 策略 | F17: — | G17: 同一批文档切出 3 种结果并统计块数
A18: 3 | B18: 11/02–11/08 | C18: 周三 | D18: Embedding 原理与你该关心的维度 | E18: Sentence Transformers | F18: — | G18: 本地跑一个 embedding 模型，算两句话相似度
A19: 3 | B19: 11/02–11/08 | C19: 周四 | D19: 向量库：Chroma / FAISS 的取舍 | E19: Chroma | F19: FAISS Wiki | G19: 建库、持久化、重启后能查
A20: 3 | B20: 11/02–11/08 | C20: 周五 | D20: 引用与溯源：答案里怎么带出处 | E20: LlamaIndex 文档 | F20: — | G20: 回答末尾附 chunk id 与原文片段
A21: 3 | B21: 11/02–11/08 | C21: 周末 | D21: 实战：把解析→切分→向量化→检索串成一条 CLI，对 5 个问题给出带引用的答案。 | E21: 检索兜底：pdf 解析 表格 保真；text splitter recursive
A22: 4 | B22: 11/09–11/15 | C22: 周一 | D22: Recall@k / MRR / NDCG 到底在算什么 | E22: IR 评估指标 | F22: — | G22: 手算 5 条样例的 Recall@3 与 MRR
A23: 4 | B23: 11/09–11/15 | C23: 周二 | D23: 用 RAGAs 从文档反向生成问题集 | E23: RAGAs 测试集生成 | F23: — | G23: 生成 30 条「问题 + 标准答案」
A24: 4 | B24: 11/09–11/15 | C24: 周三 | D24: 人工过一遍生成集：去噪、补难度分层 | E24: RAGAs 数据集概念 | F24: — | G24: 30 条里留下 20 条可用，标注易/中/难
A25: 4 | B25: 11/09–11/15 | C25: 周四 | D25: 写检索评测脚本：一个函数换策略就能跑 | E25: pytest 参数化 | F25: — | G25: `pytest eval_retrieval.py` 输出一张表
A26: 4 | B26: 11/09–11/15 | C26: 周五 | D26: 实验设计：控制变量，只改一个参数 | E26: Chunking 策略 | F26: — | G26: 3 种 chunk 策略 × 同一批问题的对比表
A27: 4 | B27: 11/09–11/15 | C27: 周末 | D27: 实战：产出「检索评测报告 v1」：指标定义、数据集说明、3 组对比、结论一句话。 | E27: 检索兜底：Recall@k 计算；ragas testset generation 中文
A28: 5 | B28: 11/16–11/22 | C28: 周一 | D28: Query 改写：Multi-Query / HyDE 的适用场景 | E28: LlamaIndex 文档 | F28: — | G28: 同一个问题生成 3 个变体并各自检索
A29: 5 | B29: 11/16–11/22 | C29: 周二 | D29: BM25 与稀疏检索：为什么它能补上向量检索的短板 | E29: rank_bm25 | F29: — | G29: BM25 单跑一次，记录 Recall@5
A30: 5 | B30: 11/16–11/22 | C30: 周三 | D30: 混合检索与 RRF 融合 | E30: RAG from Scratch | F30: — | G30: 向量 + BM25 融合后 Recall@5 提升
A31: 5 | B31: 11/16–11/22 | C31: 周四 | D31: Rerank：交叉编码器的精度与延迟代价 | E31: Cohere Rerank | F31: — | G31: 加 rerank 后 top-3 命中率与 P99 延迟
A32: 5 | B32: 11/16–11/22 | C32: 周五 | D32: 消融实验：逐个打开，看谁真的有用 | E32: RAG from Scratch | F32: — | G32: 一张四行消融表（基线/+改写/+混合/+重排）
A33: 5 | B33: 11/16–11/22 | C33: 周末 | D33: 实战：把 W3 的系统升级到「混合检索 + 重排」，在报告里写清每个改动的边际收益。 | E33: 检索兜底：hybrid search RRF；bge-reranker 本地部署
A34: 6 | B34: 11/23–11/29 | C34: 周一 | D34: Faithfulness / Answer Relevancy 怎么定义 | E34: RAGAs 指标清单 | F34: — | G34: 能解释每个指标在惩罚什么错误
A35: 6 | B35: 11/23–11/29 | C35: 周二 | D35: 跑一次完整 RAGAs 评估 | E35: RAGAs 快速开始 | F35: — | G35: 基线 vs 优化版四指标对比
A36: 6 | B36: 11/23–11/29 | C36: 周三 | D36: Milvus 单机部署与 SDK 增删改查 | E36: Milvus 文档 | F36: — | G36: Docker 起 Milvus，写入 1 万条并检索
A37: 6 | B37: 11/23–11/29 | C37: 周四 | D37: Docker 打包：镜像瘦身与启动自检 | E37: Docker 文档 | F37: — | G37: 镜像 < 1GB，启动时打印向量库连接状态
A38: 6 | B38: 11/23–11/29 | C38: 周五 | D38: 写评估报告与 README（含限制说明） | E38: Make a README | F38: — | G38: 别人 3 条命令能跑起来
A39: 6 | B39: 11/23–11/29 | C39: 周末 | D39: 实战：里程碑 M1：打 tag v0.1，README 里放指标表；把仓库链接发给… | E39: 检索兜底：ragas faithfulness 中文；milvus docker standalone
A40: 7 | B40: 11/30–12/06 | C40: 周一 | D40: Agent 与 Workflow 的边界：什么场景不该用 Agent | E40: Building effective agents | F40: — | G40: 写出 3 个「不该用 Agent」的反例
A41: 7 | B41: 11/30–12/06 | C41: 周二 | D41: ReAct：Reason + Act 的原始论文 | E41: ReAct 论文 | F41: — | G41: 画出 think→act→observe 循环图
...

Sheet 成果验收
A1: 38 周成果验收：一句话成果 / 证据 / 达标线 / 不合格的样子
A3: 周次 | B3: 日期 | C3: 本周成果（一句话） | D3: 交付证据 | E3: 达标线 | F3: 不合格的样子 | G3: 状态
A4: 1 | B4: 10/19–10/25 | C4: 能用工程化方式调用 LLM，并说清 token 计费与首 token 延迟 | D4: mini-llm-service 仓库首个 commit；`ask` 命令的录屏或 gif；一页笔记（流式与 SSE 的关系） | E4: `--stream` 逐字输出；`--debug` 打印 prompt/completion 两个 token 数；断网或超时 3 秒内报错且不崩 | F4: 直接 print 整段返回；没有超时配置；token 数靠估 | G4: 未开始
A5: 2 | B5: 10/26–11/01 | C5: 能交付一个「别人 clone 下来就能跑、能测」的服务 | D5: /chat 服务 + 8 条 pytest + Dockerfile；README 里两条命令（build / run） | E5: `pytest -q` 全绿且不需要真 key（全 mock）；镜像 < 1.2GB；curl 拿到流式 | F5: 测试要真 key、跑一次花两毛；Dockerfile 用 latest；没有 .dockerignore | G5: 未开始
A6: 3 | B6: 11/02–11/08 | C6: 能把 50 份 PDF 变成可检索、可引用答案的知识库 | D6: 索引构建脚本 + 5 问 5 答的引用截图 + 解析失败清单 | E6: 抽 3 个含表格的 PDF 人工核对不丢内容；每条答案附 chunk 原文；重建索引 < 5 分钟 | F6: 只支持 txt；引用写「来自文档」这种废话；表格解析成一团 | G6: 未开始
A7: 4 | B7: 11/09–11/15 | C7: 有一把尺子，能证明检索变好还是变坏 | D7: 30 条评测集（JSONL）+ 评测脚本 + 三种策略对比表 | E7: 人工确认 ≥20 条有效；一条命令跑完；表里同时有 Recall@5 与 MRR | F7: 让模型自己出题自己答；只写「感觉更准了」 | G7: 未开始
A8: 5 | B8: 11/16–11/22 | C8: 能用改写、混合检索、重排把指标提上去，并说清各自代价 | D8: 四行消融表（基线 / +改写 / +混合 / +重排）+ 各方案延迟 | E8: Recall@5 相对基线 ≥ +10%；每个改动的 P99 延迟增量有记录 | F8: 全开但不做消融，说不出哪一步真的有用 | G8: 未开始
A9: 6 | B9: 11/23–11/29 | C9: 能证明「答案没瞎编」，并把系统打包交付 | D9: RAGAs 四指标报告（基线 vs 优化）+ Milvus 部署脚本 + v0.1 tag | E9: Faithfulness ≥ 0.85（达不到就写清基线并说明原因）；三条命令可复现 | F9: 只贴一个分数，没有对照组 | G9: 未开始
A10: 7 | B10: 11/30–12/06 | C10: 不看框架写出 150 行 Agent Loop，并能解释循环为什么停 | D10: mini-agent 仓库 + 一次完整轨迹（JSONL，含每步耗时） | E10: 3 个工具、最大步数、超时、解析失败重试齐全；轨迹能逐步回放 | F10: `while True` 没有上限；工具调用写死在 prompt 描述里 | G10: 未开始
A11: 8 | B11: 12/07–12/13 | C11: 工具 30% 失败率下，Agent 仍能完成任务 | D11: 失败注入开关 + 三策略对比表（无重试 / 退避 / 降级） | E11: 成功率 ≤70% → ≥95%；平均步数增幅 < 30%；成本不翻倍 | F11: 只包了 try/except，没有降级路径 | G11: 未开始
A12: 9 | B12: 12/14–12/20 | C12: 能力能以 MCP Server 形式被任意客户端复用 | D12: Server 仓库 + 契约测试 + 客户端调用截图 | E12: 5 条契约用例通过（含非法参数）；错误信息可读；README 有 3 条示例 | F12: 只能在自己脚本里 import，谈不上协议 | G12: 未开始
A13: 10 | B13: 12/21–12/27 | C13: Agent 跨会话记得用户，且上下文不炸 | D13: 记忆库 + 20 轮对话日志 + 压缩前后 token 对比 | E13: 第 2 天能召回偏好；20 轮后 token 增长 < 2 倍；10 条抽查召回准确率 ≥80% | F13: 把所有历史一股脑塞进 prompt | G13: 未开始
A14: 11 | B14: 12/28–01/03 | C14: 能让 Agent 停下来等人确认，也能读懂别人的 Harness | D14: research-agent 仓库 + 中断演示 + 一页拆解笔记 | E14: 高风险动作必须人工确认；进程被杀后能续跑；笔记指出 4 个机制的具体位置 | F14: 「多 Agent 就是多写几个 prompt」 | G14: 未开始
A15: 12 | B15: 01/04–01/10 | C15: 拿得出「优化前后」的硬指标 | D15: 火焰图 + QPS/P99 前后对比 + 改动清单 | E15: QPS ≥3 倍或 P99 降 ≥50%，且成功率不变；每个改动能单独开关 | F15: 换成更贵的模型充数，还说「性能提升了」 | G15: 未开始
... A41: 38 | B41: 07/05–07/11 | C41: 38 周被压缩成 3 分钟 | D41: demo 视频 + 技术报告 + 作品集页 + 简历 v4 | E41: 外行看 3 分钟能说出你做了什么；3 个仓库置顶可点 | F41: 只剩一堆散乱的 notebook | G41: 未开始

Sheet 里程碑
A1: 六个里程碑 · 验收清单
A3: 里程碑 | B3: 目标日期 | C3: 对应周 | D3: 验收标准 | E3: 状态 | F3: 备注
A4: M1 RAG 系统 | B4: 46355 | C4: W1-W6 | D4: 30 条评测集可复跑，优化前后指标有对比表 | E4: 未开始
A5: M2 手写 Agent | B5: 46390 | C5: W7-W11 | D5: 150 行内跑通 loop，工具 / 重试 / trace 齐全 | E5: 未开始
A6: M3 可部署系统 | B6: 46418 | C6: W12-W15 | D6: compose up 一键起，有 QPS / P99 / 成本三项数据 | E6: 未开始
A7: M4 Eval Harness | B7: 46439 | C7: W17-W18 | D7: 一条命令输出通过率 / 步数 / 成本 / 失败分布 | E7: 未开始
A8: M5 两个简历项目 | B8: 46467 | C8: W19-W22 | D8: 可运行 + 可评测 + README 有取舍说明 | E8: 未开始
A9: M6 具身 pipeline | B9: 46579 | C9: W25-W38 | D9: 仿真复现 + 微调 + sim2real + 评测报告 + 视频 | E9: 未开始

Sheet 资源清单
A1: 资源清单（每个阶段只留 3 个，贪多是最大的坑）
A3: 阶段 | B3: 资源 | C3: 链接 | D3: 用途 | E3: 优先级
A4: 阶段 0-2 | B4: Anthropic: Building effective agents | C4: https://www.anthropic.com/engineering/building-effective-agents | D4: Agent 与 Workflow 的边界，必读三遍 | E4: P0
A5: 阶段 0-2 | B5: OpenAI: A practical guide to building agents | C5: openai.com/… | D5: 工程视角的 Agent 设计 | E5: P1
A6: 阶段 0-2 | B6: Hello-Agents（Datawhale） | C6: https://datawhalechina.github.io/hello-agents/ | D6: 中文 Agent 主线教材 | E6: P0
A7: 阶段 1 | B7: All-in-RAG（Datawhale） | C7: https://github.com/datawhalechina/all-in-rag | D7: RAG 系统化实现 | E7: P0
A8: 阶段 1 | B8: RAG from Scratch | C8: https://github.com/langchain-ai/rag-from-scratch | D8: 检索技术速查 | E8: P1
A9: 阶段 1 | B9: RAGAs | C9: https://docs.ragas.io/ | D9: RAG 自动评估 | E9: P0
A10: 阶段 2 | B10: MCP 协议 | C10: https://modelcontextprotocol.io/ | D10: 工具生态事实标准 | E10: P0
A11: 阶段 2 | B11: LangGraph | C11: https://langchain-ai.github.io/langgraph/ | D11: 状态机、中断、人工确认 | E11: P0
A12: 阶段 2 | B12: learn-claude-code | C12: https://github.com/shareAI-lab/learn-claude-code | D12: 从零复刻 coding agent harness | E12: P1
A13: 阶段 3 | B13: Langfuse | C13: https://langfuse.com/ | D13: 开源 trace，适合自建 | E13: P0
A14: 阶段 3 | B14: vLLM | C14: https://docs.vllm.ai/ | D14: 推理加速与吞吐测试 | E14: P1
... A24: 阶段 B | B24: NVIDIA Physical AI 课程 | C24: https://docs.nvidia.com/learning/physical-ai/robotics.html | D24: 含 SO-101 sim2real 完整流程 | E24: P1
